Workbook

Sheet Ours
D1: From | E1: Dest | F1: From | G1: Lenth | H1: Dest | I1: B3 | J1: B4 | K1: B5 | L1: B6 | M1: B7 | N1: B8
B2: Radio Buttons
A3: Verified | B3: Poll CD | D3: =VLOOKUP(F3,Format!G:H,2,FALSE) -> Radio | E3: =VLOOKUP(H3,Format!G:H,2,FALSE) -> CD player | F3: 68 | G3: 03 | H3: 18 | I3: 01 | J3: 72 | O3: 68 3 18 1 72
A4: Verified | B4: (radio on) no button press | D4: =VLOOKUP(F4,Format!G:H,2,FALSE) -> Radio | E4: =VLOOKUP(H4,Format!G:H,2,FALSE) -> General news 2 | F4: 68 | G4: 04 | H4: FF | I4: 3B | J4: 00 | K4: A8 | O4: 68 4 FF 3B 0 A8
B5: CD status Req | D5: =VLOOKUP(F5,Format!G:H,2,FALSE) -> Radio | E5: =VLOOKUP(H5,Format!G:H,2,FALSE) -> CD player | F5: 68 | G5: 05 | H5: 18 | I5: 38 | J5: 00 | K5: 00 | L5: 4D | N5: "request pause" | V5: 68 5 18 38 1 0 4C ibus good
A6: Veified | B6: Stop | D6: =VLOOKUP(F6,Format!G:H,2,FALSE) -> Radio | E6: =VLOOKUP(H6,Format!G:H,2,FALSE) -> CD player | F6: 68 | G6: 05 | H6: 18 | I6: 38 | J6: 01 | K6: 00 | L6: 4C | N6: (sent when changing to other mode or off)
A7: Verified | B7: Pause | D7: =VLOOKUP(F7,Format!G:H,2,FALSE) -> Radio | E7: =VLOOKUP(H7,Format!G:H,2,FALSE) -> CD player | F7: 68 | G7: 05 | H7: 18 | I7: 38 | J7: 02 | K7: 00 | L7: 4F | O7: 68 5 18 38 2 0 4F
A8: Veified | B8: Play | D8: =VLOOKUP(F8,Format!G:H,2,FALSE) -> Radio | E8: =VLOOKUP(H8,Format!G:H,2,FALSE) -> CD player | F8: 68 | G8: 05 | H8: 18 | I8: 38 | J8: 03 | K8: 00 | L8: 4E
A9: Veified | B9: Fast Rwd | D9: =VLOOKUP(F9,Format!G:H,2,FALSE) -> Radio | E9: =VLOOKUP(H9,Format!G:H,2,FALSE) -> CD player | F9: 68 | G9: 05 | H9: 18 | I9: 38 | J9: 04 | K9: 00 | L9: 49 | N9: (when in manual mode or skip right is held down)
A10: Veified | B10: Fast Fwd | D10: =VLOOKUP(F10,Format!G:H,2,FALSE) -> Radio | E10: =VLOOKUP(H10,Format!G:H,2,FALSE) -> CD player | F10: 68 | G10: 05 | H10: 18 | I10: 38 | J10: 04 | K10: 01 | L10: 48 | N10: (when in manual mode or skip right is held down)
A12: Verified | B12: CD Button 1 | D12: =VLOOKUP(F12,Format!G:H,2,FALSE) -> Radio | E12: =VLOOKUP(H12,Format!G:H,2,FALSE) -> CD player | F12: 68 | G12: 05 | H12: 18 | I12: 38 | J12: 06 | K12: 01 | L12: 4A
A13: Verified | B13: CD Button 2 | D13: =VLOOKUP(F13,Format!G:H,2,FALSE) -> Radio | E13: =VLOOKUP(H13,Format!G:H,2,FALSE) -> CD player | F13: 68 | G13: 05 | H13: 18 | I13: 38 | J13: 06 | K13: 02
A14: Verified | B14: CD Button 3 | D14: =VLOOKUP(F14,Format!G:H,2,FALSE) -> Radio | E14: =VLOOKUP(H14,Format!G:H,2,FALSE) -> CD player | F14: 68 | G14: 05 | H14: 18 | I14: 38 | J14: 06 | K14: 03
A15: Verified | B15: CD Button 4 | D15: =VLOOKUP(F15,Format!G:H,2,FALSE) -> Radio | E15: =VLOOKUP(H15,Format!G:H,2,FALSE) -> CD player | F15: 68 | G15: 05 | H15: 18 | I15: 38 | J15: 06 | K15: 04 | T15: B4 | V15: B5 - button number or:
A16: Verified | B16: CD Button 5 | D16: =VLOOKUP(F16,Format!G:H,2,FALSE) -> Radio | E16: =VLOOKUP(H16,Format!G:H,2,FALSE) -> CD player | F16: 68 | G16: 05 | H16: 18 | I16: 38 | J16: 06 | K16: 05 | T16: 00 | U16: on and Pause | V16: 00 | W16: Off
A17: Verified | B17: CD Button 6 | D17: =VLOOKUP(F17,Format!G:H,2,FALSE) -> Radio | E17: =VLOOKUP(H17,Format!G:H,2,FALSE) -> CD player | F17: 68 | G17: 05 | H17: 18 | I17: 38 | J17: 06 | K17: 06 | T17: 01 | U17: Stop | V17: 01 | W17: On
T18: 02 | U18: Pause | V18: 02
A19: Verified | B19: Scan On | D19: =VLOOKUP(F19,Format!G:H,2,FALSE) -> Radio | E19: =VLOOKUP(H19,Format!G:H,2,FALSE) -> CD player | F19: 68 | G19: 05 | H19: 18 | I19: 38 | J19: 07 | K19: 01 | L19: 4B | T19: 03 | U19: Play
A20: Verified | B20: Scan Off | D20: =VLOOKUP(F20,Format!G:H,2,FALSE) -> Radio | E20: =VLOOKUP(H20,Format!G:H,2,FALSE) -> CD player | F20: 68 | G20: 05 | H20: 18 | I20: 38 | J20: 07 | K20: 00 | L20: 4A | T20: 04 | U20: Fst RWD
T21: 05
A22: Verified | B22: Random On | D22: =VLOOKUP(F22,Format!G:H,2,FALSE) -> Radio | E22: =VLOOKUP(H22,Format!G:H,2,FALSE) -> CD player | F22: 68 | G22: 05 | H22: 18 | I22: 38 | J22: 08 | K22: 01 | L22: 44 | T22: 06 | U22: Button
A23: Verified | B23: Random Off | D23: =VLOOKUP(F23,Format!G:H,2,FALSE) -> Radio | E23: =VLOOKUP(H23,Format!G:H,2,FALSE) -> CD player | F23: 68 | G23: 05 | H23: 18 | I23: 38 | J23: 08 | K23: 00 | L23: 45 | T23: 07 | U23: Scan
T24: 08 | U24: Random
A25: Verified | B25: Skip forward | D25: =VLOOKUP(F25,Format!G:H,2,FALSE) -> Radio | E25: =VLOOKUP(H25,Format!G:H,2,FALSE) -> CD player | F25: 68 | G25: 04 | H25: 18 | I25: 0A | J25: 00 | K25: 47 | T25: 09
A26: Verified | B26: Skip Backward | D26: =VLOOKUP(F26,Format!G:H,2,FALSE) -> Radio | E26: =VLOOKUP(H26,Format!G:H,2,FALSE) -> CD player | F26: 68 | G26: 04 | H26: 18 | I26: 0A | J26: 01 | K26: 46 | T26: 0A
B27: Skip forward green car | F27: 68 | G27: 05 | H27: 18 | I27: 38 | J27: 5 | K27: 0 | L27: 48 | T27: 0B
B28: Skip backward forward green car | F28: 68 | G28: 05 | H28: 18 | I28: 38 | J28: 5 | K28: 1 | L28: 49 | T28: 0C
B29: Release | F29: 68 | G29: 05 | H29: 18 | I29: 38 | J29: 3 | K29: 0 | L29: 4E | O29: update text when rec'd | T29: 0D
T30: 0E
T31: 0F
B32: CD Player | T32: 10
B33: (From CD changer $18h)
A34: verified | B34: Cd Announce | D34: =VLOOKUP(F34,Format!G:H,2,FALSE) -> CD player | E34: =VLOOKUP(H34,Format!G:H,2,FALSE) -> General news 2 | F34: 18 | G34: 04 | H34: FF | I34: 02 | J34: 01 | K34: E0 | L34: registration message (after reset)
A35: verified | B35: CD respond | D35: =VLOOKUP(F35,Format!G:H,2,FALSE) -> CD player | E35: =VLOOKUP(H35,Format!G:H,2,FALSE) -> General news 2 | F35: 18 | G35: 04 | H35: FF | I35: 02 | J35: 00 | K35: E1 | L35: Response
B38: CD Status | J38: B4 | K38: B5 | L38: B6 | M38: B7 | N38: B8 | O38: Disk | P38: track
B39: CD not Play | D39: =VLOOKUP(F39,Format!G:H,2,FALSE) -> CD player | E39: =VLOOKUP(H39,Format!G:H,2,FALSE) -> Radio | F39: 18 | G39: 0A | H39: 68 | I39: 39 | J39: 00 | K39: 02 | L39: 00 | M39: 3F | N39: 00 | O39: 00 | P39: 00 | R39: Stop | S39: Requst = Pause | Z39: with ending 01 01 checksum is 7E
B40: CD start Play | D40: =VLOOKUP(F40,Format!G:H,2,FALSE) -> CD player | E40: =VLOOKUP(H40,Format!G:H,2,FALSE) -> Radio | F40: 18 | G40: 0A | H40: 68 | I40: 39 | J40: 01 | K40: 09 | L40: 00 | M40: 3F | N40: 00 | O40: 00 | P40: 00 | R40: Pause | S40: Requst = Play
B41: CD Playing | D41: =VLOOKUP(F41,Format!G:H,2,FALSE) -> CD player | E41: =VLOOKUP(H41,Format!G:H,2,FALSE) -> Radio | F41: 18 | G41: 0A | H41: 68 | I41: 39 | J41: 02 | K41: 09 | L41: 00 | M41: 3F | N41: 00 | O41: 00 | P41: 00 | R41: Play | S41: Requst = Play
B42: CD scan FWD | D42: =VLOOKUP(F42,Format!G:H,2,FALSE) -> CD player | E42: =VLOOKUP(H42,Format!G:H,2,FALSE) -> Radio | F42: 18 | G42: 0A | H42: 68 | I42: 39 | J42: 03 | K42: 09 | L42: 00 | M42: 3F | N42: 00 | O42: 00 | P42: 00 | R42: FFWD | S42: Requst = Play
B43: CD Scan BWD | D43: =VLOOKUP(F43,Format!G:H,2,FALSE) -> CD player | E43: =VLOOKUP(H43,Format!G:H,2,FALSE) -> Radio | F43: 18 | G43: 0A | H43: 68 | I43: 39 | J43: 04 | K43: 09 | L43: 00 | M43: 3F | N43: 00 | O43: 00 | P43: 00 | R43: FRWD | S43: Requst = Play
...

Sheet Codes
D1: From | E1: Dest | F1: From | G1: Lenth | H1: Dest | I1: B3 | J1: B4 | K1: B5 | L1: B6 | M1: B7 | N1: B8
A2: 'STEERING WHEEL | B2: Steering Wheel <50, 04, 68>
A3: volup BYTE $50, $04, $68, $32, $11 | B3: Voume up | C3: $50, $04, $68, $32, $11 | D3: =VLOOKUP(F3,Format!G:H,2,FALSE) -> Steering Wheel | E3: =VLOOKUP(H3,Format!G:H,2,FALSE) -> Radio | F3: 50 | G3: 04 | H3: 68 | I3: 32 | J3: 11
A4: voldown BYTE $50, $04, $68, $32, $10 | B4: Volume Down | C4: $50, $04, $68, $32, $10 | D4: =VLOOKUP(F4,Format!G:H,2,FALSE) -> Steering Wheel | E4: =VLOOKUP(H4,Format!G:H,2,FALSE) -> Radio | F4: 50 | G4: 04 | H4: 68 | I4: 32 | J4: 10
A5: whlplus BYTE $50, $04, $68, $3B, $01 | B5: Wheel next | C5: $50, $04, $68, $3B, $01 | D5: =VLOOKUP(F5,Format!G:H,2,FALSE) -> Steering Wheel | E5: =VLOOKUP(H5,Format!G:H,2,FALSE) -> Radio | F5: 50 | G5: 04 | H5: 68 | I5: 3B | J5: 01
A6: whlmin BYTE $50, $04, $68, $3B, $08 | B6: Wheel skip | C6: $50, $04, $68, $3B, $08 | D6: =VLOOKUP(F6,Format!G:H,2,FALSE) -> Steering Wheel | E6: =VLOOKUP(H6,Format!G:H,2,FALSE) -> Radio | F6: 50 | G6: 04 | H6: 68 | I6: 3B | J6: 01
A7: RTButton BYTE $50, $04, $C8, $3B, $40 | B7: RT Button | C7: $50, $04, $C8, $3B, $40 | D7: =VLOOKUP(F7,Format!G:H,2,FALSE) -> Steering Wheel | E7: =VLOOKUP(H7,Format!G:H,2,FALSE) -> Tel | F7: 50 | G7: 04 | H7: C8 | I7: 3B | J7: 40
A8: Dial BYTE $50, $04, $C8, $3B, $80 | B8: Dial | C8: $50, $04, $C8, $3B, $80 | D8: =VLOOKUP(F8,Format!G:H,2,FALSE) -> Steering Wheel | E8: =VLOOKUP(H8,Format!G:H,2,FALSE) -> Tel | F8: 50 | G8: 04 | H8: C8 | I8: 3B | J8: 80
A10: 'WINDOWS and MIRRORS | B10: Windows and Mirrors
A11: DRwindOpen BYTE $3F, $05, $00, $0C, $41, $01 | B11: DR wind Open | C11: $3F, $05, $00, $0C, $41, $01 | D11: =VLOOKUP(F11,Format!G:H,2,FALSE) -> DIS Unknown | E11: =VLOOKUP(H11,Format!G:H,2,FALSE) -> General news 1 | F11: 3F | G11: 05 | H11: 00 | I11: 0C | J11: 41 | K11: 01 | P11: Messages to the control units for the E39 series: address 00 Hex (transmitter 3FH / DIS)
A12: DRwindClose BYTE $3F, $05, $00, $0C, $42, $01 | B12: DR wind Close | C12: $3F, $05, $00, $0C, $42, $01 | D12: =VLOOKUP(F12,Format!G:H,2,FALSE) -> DIS Unknown | E12: =VLOOKUP(H12,Format!G:H,2,FALSE) -> General news 1 | F12: 3F | G12: 05 | H12: 00 | I12: 0C | J12: 42 | K12: 01 | P12: <3F 05 00> 0C 00 44 <XOR> Fenster Fahrerseite hinten schließen <3F 05 00> 00 44 0C <XOR> driver's side window close behind | AJ12: =RIGHT(LEFT(P12,19),2) -> 44 | AK12: =HEX2BIN(AJ12,8) -> 01000100 | AL12: 1001100 | AM12: =BIN2HEX(AL12,8) -> 0000004C | AN12: 34
A13: PRwindClose BYTE $3F, $05, $00, $0C, $43, $01 | B13: PR wind close | C13: $3F, $05, $00, $0C, $43, $01 | D13: =VLOOKUP(F13,Format!G:H,2,FALSE) -> DIS Unknown | E13: =VLOOKUP(H13,Format!G:H,2,FALSE) -> General news 1 | F13: 3F | G13: 05 | H13: 00 | I13: 0C | J13: 43 | K13: 01 | P13: <3F 05 00> 0C 00 45 <XOR> Fenster Fahrerseite hinten öffnen <3F 05 00> 00 45 0C <XOR> driver's side window open behind | AJ13: =RIGHT(LEFT(P13,19),2) -> 45 | AK13: =HEX2BIN(AJ13,8) -> 01000101 | AL13: 1001001 | AM13: =BIN2HEX(AL13,8) -> 00000049 | AN13: 35
A14: PRwindOpen BYTE $3F, $05, $00, $0C, $44, $01 | B14: PR wind open | C14: $3F, $05, $00, $0C, $44, $01 | D14: =VLOOKUP(F14,Format!G:H,2,FALSE) -> DIS Unknown | E14: =VLOOKUP(H14,Format!G:H,2,FALSE) -> General news 1 | F14: 3F | G14: 05 | H14: 00 | I14: 0C | J14: 44 | K14: 01 | P14: <3F 05 00> 0C 00 46 <XOR> Fenster Beifahrerseite hinten schließen <3F 05 00> 00 46 0C <XOR> passenger side window close behind | AJ14: =RIGHT(LEFT(P14,19),2) -> 46 | AK14: =HEX2BIN(AJ14,8) -> 01000110 | AL14: 1001010 | AM14: =BIN2HEX(AL14,8) -> 0000004A | AN14: 36
A15: DFwindOpen BYTE $3F, $05, $00, $0C, $52, $01 | B15: DF wind open | C15: $3F, $05, $00, $0C, $52, $01 | D15: =VLOOKUP(F15,Format!G:H,2,FALSE) -> DIS Unknown | E15: =VLOOKUP(H15,Format!G:H,2,FALSE) -> General news 1 | F15: 3F | G15: 05 | H15: 00 | I15: 0C | J15: 52 | K15: 01 | P15: <3F 05 00> 0C 00 47 <XOR> Fenster Beifahrerseite hinten öffnen <3F 05 00> 00 47 0C <XOR> open rear passenger side window | AJ15: =RIGHT(LEFT(P15,19),2) -> 47 | AK15: =HEX2BIN(AJ15,8) -> 01000111 | AL15: 1001011 | AM15: =BIN2HEX(AL15,8) -> 0000004B | AN15: 37
A16: DFwindClose BYTE $3F, $05, $00, $0C, $53, $01 | B16: DF wind close | C16: $3F, $05, $00, $0C, $53, $01 | D16: =VLOOKUP(F16,Format!G:H,2,FALSE) -> DIS Unknown | E16: =VLOOKUP(H16,Format!G:H,2,FALSE) -> General news 1 | F16: 3F | G16: 05 | H16: 00 | I16: 0C | J16: 53 | K16: 01 | P16: <3F 05 00> 0C 00 65 <XOR> alle Fenster öffnen <3F 05 00> 00 65 0C <XOR> open all windows | AJ16: =RIGHT(LEFT(P16,19),2) -> 65 | AK16: =HEX2BIN(AJ16,8) -> 01100101
A17: PFwindOpen BYTE $3F, $05, $00, $0C, $54, $01 | B17: PF wind open | C17: $3F, $05, $00, $0C, $54, $01 | D17: =VLOOKUP(F17,Format!G:H,2,FALSE) -> DIS Unknown | E17: =VLOOKUP(H17,Format!G:H,2,FALSE) -> General news 1 | F17: 3F | G17: 05 | H17: 00 | I17: 0C | J17: 54 | K17: 01 | P17: <3F 05 00> 0C 00 66 <XOR> Schiebedach öffnen <3F 05 00> 00 66 0C <XOR> open sunroof | AJ17: =RIGHT(LEFT(P17,19),2) -> 66 | AK17: =HEX2BIN(AJ17,8) -> 01100110
A18: PFwindClose BYTE $3F, $05, $00, $0C, $55, $01 | B18: PF wind Close | C18: $3F, $05, $00, $0C, $55, $01 | D18: =VLOOKUP(F18,Format!G:H,2,FALSE) -> DIS Unknown | E18: =VLOOKUP(H18,Format!G:H,2,FALSE) -> General news 1 | F18: 3F | G18: 05 | H18: 00 | I18: 0C | J18: 55 | K18: 01 | P18: <3F 05 00> 0C 00 0B <XOR> Zentralverriegelung öffen/schließen <3F 05 00> 0C 00 0B <XOR> Central close openable / | AJ18: =RIGHT(LEFT(P18,19),2) -> 0B | AK18: =HEX2BIN(AJ18,8) -> 00001011
P19: <3F 05 00> 0C 00 40 <XOR> Kofferraum öffnen <3F 05 00> 00 40 0C <XOR> trunk open | AJ19: =RIGHT(LEFT(P19,19),2) -> 40 | AK19: =HEX2BIN(AJ19,8) -> 01000000
A20: SRoofClose BYTE $3F, $05, $00, $0C, $7F, $01 | B20: Sun Roof Close | C20: $3F, $05, $00, $0C, $7F, $01 | D20: =VLOOKUP(F20,Format!G:H,2,FALSE) -> DIS Unknown | E20: =VLOOKUP(H20,Format!G:H,2,FALSE) -> General news 1 | F20: 3F | G20: 05 | H20: 00 | I20: 0C | J20: 7F | K20: 01 | P20: <3F 05 00> 0C 00 00 <XOR> Fahrersitz nach vorne verschieben <3F 05 00> 00 00 0C <XOR> seat move forward | AJ20: =RIGHT(LEFT(P20,19),2) -> 00 | AK20: =HEX2BIN(AJ20,8) -> 00000000
A21: SRoofOpen BYTE $3F, $05, $00, $0C, $7E, $01 | B21: Sun Roof Open | C21: $3F, $05, $00, $0C, $7E, $01 | D21: =VLOOKUP(F21,Format!G:H,2,FALSE) -> DIS Unknown | E21: =VLOOKUP(H21,Format!G:H,2,FALSE) -> General news 1 | F21: 3F | G21: 05 | H21: 00 | I21: 0C | J21: 7E | K21: 01 | P21: <3F 05 00> 0C 00 01 <XOR> Fahrersitz nach hinten verschieben <3F 05 00> 00 01 0C <XOR> seat rearwards | AJ21: =RIGHT(LEFT(P21,19),2) -> 01 | AK21: =HEX2BIN(AJ21,8) -> 00000001
P22: <3F 06 00> 0C 01 31 01 <XOR> Spiegel Fahrerseite einklappen <3F 06 00> 01 31 01 0C <XOR> driver side mirror fold | AJ22: =RIGHT(LEFT(P22,19),2) -> 31 | AK22: =HEX2BIN(AJ22,8) -> 00110001
A23: DMirrorFold BYTE $3F, $06, $00, $0C, $01, $31, $01 | B23: D Mirror Fold | C23: $3F, $06, $00, $0C, $01, $31, $01 | D23: =VLOOKUP(F23,Format!G:H,2,FALSE) -> DIS Unknown | E23: =VLOOKUP(H23,Format!G:H,2,FALSE) -> General news 1 | F23: 3F | G23: 06 | H23: 00 | I23: 0C | J23: 01 | K23: 31 | L23: 01 | P23: <3F 06 00> 0C 01 30 01 <XOR> Spiegel Fahrerseite ausklappen <3F 06 00> 01 30 01 0C <XOR> driver side mirror fold out | AJ23: =RIGHT(LEFT(P23,19),2) -> 30 | AK23: =HEX2BIN(AJ23,8) -> 00110000
A24: DMirrorOut BYTE $3F, $06, $00, $0C, $01, $30, $01 | B24: D Mirror Out | C24: $3F, $06, $00, $0C, $01, $30, $01 | D24: =VLOOKUP(F24,Format!G:H,2,FALSE) -> DIS Unknown | E24: =VLOOKUP(H24,Format!G:H,2,FALSE) -> General news 1 | F24: 3F | G24: 06 | H24: 00 | I24: 0C | J24: 01 | K24: 30 | L24: 01 | P24: <3F 06 00> 0C 02 31 01 <XOR> Spiegel Beifahrerseite einklappen <3F 06 00> 02 31 01 0C <XOR> passenger side mirror fold | AJ24: =RIGHT(LEFT(P24,19),2) -> 31 | AK24: =HEX2BIN(AJ24,8) -> 00110001
A25: PMirrorFold BYTE $3F, $06, $00, $0C, $02, $31, $01 | B25: P Mirror Fold | C25: $3F, $06, $00, $0C, $02, $31, $01 | D25: =VLOOKUP(F25,Format!G:H,2,FALSE) -> DIS Unknown | E25: =VLOOKUP(H25,Format!G:H,2,FALSE) -> General news 1 | F25: 3F | G25: 06 | H25: 00 | I25: 0C | J25: 02 | K25: 31 | L25: 01 | P25: <3F 06 00> 0C 02 30 01 <XOR> Spiegel Beifahrerseite ausklappen <3F 06 00> 02 30 01 0C <XOR> passenger side mirror fold out | AJ25: =RIGHT(LEFT(P25,19),2) -> 30 | AK25: =HEX2BIN(AJ25,8) -> 00110000
A26: PMirrorOut BYTE $3F, $06, $00, $0C, $02, $30, $01 | B26: P Mirror Out | C26: $3F, $06, $00, $0C, $02, $30, $01 | D26: =VLOOKUP(F26,Format!G:H,2,FALSE) -> DIS Unknown | E26: =VLOOKUP(H26,Format!G:H,2,FALSE) -> General news 1 | F26: 3F | G26: 06 | H26: 00 | I26: 0C | J26: 02 | K26: 30 | L26: 01
A28: 'LIGHTS | B28: Lights
A29: ClownNose BYTE $3F, $05, $00, $0C, $4E, $01 | B29: Clown Nose | C29: $3F, $05, $00, $0C, $4E, $01 | D29: =VLOOKUP(F29,Format!G:H,2,FALSE) -> DIS Unknown | E29: =VLOOKUP(H29,Format!G:H,2,FALSE) -> General news 1 | F29: 3F | G29: 05 | H29: 00 | I29: 0C | J29: 4E | K29: 01 | AG29: dr w o | AH29: 41 | AI29: =HEX2BIN(AH29,8) -> 01000001
A30: Wrnblnk BYTE $3f, $0b, $bf, $0c, $20, $00, $00, $00, $00, $00, $00, $06 | B30: Wrn Blnk | C30: $3f, $0b, $bf, $0c, $20, $00, $00, $00, $00, $00, $00, $06 | D30: =VLOOKUP(F30,Format!G:H,2,FALSE) -> DIS Unknown | E30: =VLOOKUP(H30,Format!G:H,2,FALSE) -> LCM, Global | F30: 3f | G30: 0b | H30: bf | I30: 0c | J30: 20 | K30: 00 | L30: 00 | M30: 00 | N30: 00 | O30: 00 | P30: 00 | Q30: 06 | AG30: dr w c | AH30: 42 | AI30: =HEX2BIN(AH30,8) -> 01000010
A31: Wrnblnk3sec BYTE $3f, $05, $00, $0c, $75, $01 | B31: Wrn Blnk 3sec | C31: $3f, $05, $00, $0c, $75, $01 | D31: =VLOOKUP(F31,Format!G:H,2,FALSE) -> DIS Unknown | E31: =VLOOKUP(H31,Format!G:H,2,FALSE) -> General news 1 | F31: 3f | G31: 05 | H31: 00 | I31: 0c | J31: 75 | K31: 01 | AG31: df w o | AH31: 52 | AI31: =HEX2BIN(AH31,8) -> 01010010
A32: ParkLeft BYTE $3f, $0b, $bf, $0c, $00, $00, $00, $40, $00, $00, $00, $06 | B32: Park Left | C32: $3f, $0b, $bf, $0c, $00, $00, $00, $40, $00, $00, $00, $06 | D32: =VLOOKUP(F32,Format!G:H,2,FALSE) -> DIS Unknown | E32: =VLOOKUP(H32,Format!G:H,2,FALSE) -> LCM, Global | F32: 3f | G32: 0b | H32: bf | I32: 0c | J32: 00 | K32: 00 | L32: 00 | M32: 40 | N32: 00 | O32: 00 | P32: 00 | Q32: 06 | AG32: df w c | AH32: 53 | AI32: =HEX2BIN(AH32,8) -> 01010011
A33: ParkRight BYTE $3f, $0b, $bf, $0c, $00, $00, $00, $80, $00, $00, $00, $06 | B33: Park Right | C33: $3f, $0b, $bf, $0c, $00, $00, $00, $80, $00, $00, $00, $06 | D33: =VLOOKUP(F33,Format!G:H,2,FALSE) -> DIS Unknown | E33: =VLOOKUP(H33,Format!G:H,2,FALSE) -> LCM, Global | F33: 3f | G33: 0b | H33: bf | I33: 0c | J33: 00 | K33: 00 | L33: 00 | M33: 80 | N33: 00 | O33: 00 | P33: 00 | Q33: 06
A35: StopLeft BYTE $3f, $0b, $bf, $0c, $00, $00, $00, $00, $08, $00, $00, $06 | B35: Stop Left | C35: $3f, $0b, $bf, $0c, $00, $00, $00, $00, $08, $00, $00, $06 | D35: =VLOOKUP(F35,Format!G:H,2,FALSE) -> DIS Unknown | E35: =VLOOKUP(H35,Format!G:H,2,FALSE) -> LCM, Global | F35: 3f | G35: 0b | H35: bf | I35: 0c | J35: 00 | K35: 00 | L35: 00 | M35: 00 | N35: 08 | O35: 00 | P35: 00 | Q35: 06
A36: StopRight BYTE $3f, $0b, $bf, $0c, $00, $00, $00, $00, $10, $00, $00, $06 | B36: Stop Right | C36: $3f, $0b, $bf, $0c, $00, $00, $00, $00, $10, $00, $00, $06 | D36: =VLOOKUP(F36,Format!G:H,2,FALSE) -> DIS Unknown | E36: =VLOOKUP(H36,Format!G:H,2,FALSE) -> LCM, Global | F36: 3f | G36: 0b | H36: bf | I36: 0c | J36: 00 | K36: 00 | L36: 00 | M36: 00 | N36: 10 | O36: 00 | P36: 00 | Q36: 06
A38: InteriorOut BYTE $3F, $05, $00, $0C, $68, $01 | B38: Interior Out | C38: $3F, $05, $00, $0C, $68, $01 | D38: =VLOOKUP(F38,Format!G:H,2,FALSE) -> DIS Unknown | E38: =VLOOKUP(H38,Format!G:H,2,FALSE) -> General news 1 | F38: 3F | G38: 05 | H38: 00 | I38: 0C | J38: 68 | K38: 01 | L38: 5F
A40: FogLightsON BYTE $3f, $0b, $bf, $0c, $00, $00, $00, $00, $00, $00, $01, $06 | B40: Fog Light on | C40: $3f, $0b, $bf, $0c, $00, $00, $00, $00, $00, $00, $01, $06 | D40: =VLOOKUP(F40,Format!G:H,2,FALSE) -> DIS Unknown | E40: =VLOOKUP(H40,Format!G:H,2,FALSE) -> LCM, Global | F40: 3f | G40: 0b | H40: bf | I40: 0c | J40: 00 | K40: 00 | L40: 00 | M40: 00 | N40: 00 | O40: 00 | P40: 01 | Q40: 06
A41: FogLightsOFF BYTE $3f, $0b, $bf, $0c, $00, $00, $00, $00, $00, $00, $00, $06 | B41: Fog Light off | C41: $3f, $0b, $bf, $0c, $00, $00, $00, $00, $00, $00, $00, $06 | D41: =VLOOKUP(F41,Format!G:H,2,FALSE) -> DIS Unknown | E41: =VLOOKUP(H41,Format!G:H,2,FALSE) -> LCM, Global | F41: 3f | G41: 0b | H41: bf | I41: 0c | J41: 00 | K41: 00 | L41: 00 | M41: 00 | N41: 00 | O41: 00 | P41: 00 | Q41: 06
A43: HazzAndInt BYTE $3F, $05, $00, $0C, $70, $01 | B43: Hazz and Int | C43: $3F, $05, $00, $0C, $70, $01 | D43: =VLOOKUP(F43,Format!G:H,2,FALSE) -> DIS Unknown | E43: =VLOOKUP(H43,Format!G:H,2,FALSE) -> General news 1 | F43: 3F | G43: 05 | H43: 00 | I43: 0C | J43: 70 | K43: 01 | L43: 47
B45: Lighting control | D45: =VLOOKUP(F45,Format!G:H,2,FALSE) -> General news 1 | E45: =VLOOKUP(H45,Format!G:H,2,FALSE) -> CDCD | F45: 00 | G45: 04 | H45: 76 | J45: 00 04 76 bf xx chk | Q45: xx is a bitmask as follows 7 6 5 4 3 2 1 0 | AA45: Bit 1 = warning lights, bit 2 = low beam, bit 3 = Fade. The bits can be combined. eg passing and hazard lights = 0 0 0 0 0 1 1 0 = $ 06 (hex)
A48: 'LOCKS | B48: Locks
A49: remoteHome BYTE $00, $04, $BF, $72, $26 | B49: Remote Home | C49: $00, $04, $BF, $72, $26 | D49: =VLOOKUP(F49,Format!G:H,2,FALSE) -> General news 1 | E49: =VLOOKUP(H49,Format!G:H,2,FALSE) -> LCM, Global | F49: 00 | G49: 04 | H49: BF | I49: 72 | J49: 26
...

Sheet Format
A1: Source ID | B1: Length | C1: Dest ID | D1: Data | E1: XOR CRC | G1: ID Hex | H1: Location
G2: 00 | H2: General news 1 | I2: gm
C3: Length is all but first 2 bytes | G3: =0 -> 0 | H3: General news 1
G4: 01 | H4: MID1
G5: 02 | H5: EKM
G6: 08 | H6: SHD
G7: 09 | H7: ZKE
G8: 12 | H8: DME
G9: 18 | H9: CD player | I9: CDC
G10: 24 | H10: HKM
G11: 28 | H11: FUM
G12: 30 | H12: CCM
G13: 30 | H13: SES (voice Command)
G14: 40 | H14: FBZV
G15: 43 | H15: MENU SCREEN OR GTF
G16: 43 | H16: Menu Screen
G17: 44 | H17: Immobilizer | I17: EWS
G18: 46 | H18: CID
G19: 47 | H19: FMBT
G20: 50 | H20: Steering Wheel
G21: 51 | H21: MML
G22: 60 | H22: PDC
G23: 66 | H23: AHL
G24: 68 | H24: Radio
G25: =68 -> 68 | H25: Radio
G26: 70 | H26: RDC
G27: 72 | H27: SM
G28: 73 | H28: SDRS
G29: 76 | H29: CDCD
G30: 80 | H30: IKE
G31: 80 | H31: IKE
G32: 3B | H32: NAV OR GT
G33: 3B | H33: Video Module (Nav)
G34: 3F | H34: DIS Unknown
G35: 5B | H35: IHKA
G36: 5B | H36: IHKA
G37: 6A | H37: DSP
G38: 6A | H38: DSP
G39: 7F | H39: GPS Module
G40: 7F | H40: NAVE
...

Sheet Radio Sends
A1: Button | B1: Radio Reponse via ibus | J1: IPOD
A2: 1 | B2: "button 1" | J2: Switching to Mode 4 pauses ipod.
A3: 2 | B3: "button 2"
A4: 3 | B4: "button 3"
A5: 4 | B5: "button 4"
A6: 5 | B6: "button 5"
A7: 6 | B7: "button 6" | C7: Note does not send if on that CD already.
A9: RND
A10: to off | B10: Play, Random off
A11: to on | B11: Play, Random on
A13: scan
A14: to Scan on | B14: Play, Random off, scan on | C14: if Random on to start
A15: to Scan on | B15: Play, Scan on
A16: to Scan off | B16: Play, Scan off
A18: Skip right | B18: right
A19: skip left | B19: left
A20: FFWD | B20: FFWD, Play (Play when released)
A21: FRWD | B21: FRWD, Play (play when released)
A23: M | B23: Play when pressed twice
A24: M if on | B24: Right arrow is FFWD, Left FRWD
A26: Any radio button | B26: stop

Sheet Misc
A1: char rad_cdc_devstatusrequest [] = {0x68, 0x03, 0x18, 0x01, 0x72}; | C1: 5B 05 80 83 00 00 5D | D1: AC Off
A2: char cdc_rad_devstatready [] = {0x18, 0x04, 0x68, 0x02, 0x00};//, 0x76}; | C2: 5B 05 80 83 80 08 D5 | D2: AC on
C3: 5B 05 80 83 C5 00 98 | D3: AC on
A4: char rad_cdc_cdconstrolstop [] = {0x68, 0x05, 0x18, 0x38, 0x01, 0x00, | C4: 80 05 BF 18 00 00 22 | D4: RPM
A5: 0x4C}; | C5: 80 06 BF 19 11 14 00 25 | D5: Temp
A6: char rad_cdc_cdcontrolstatrequest [] = {0x68, 0x05, 0x18, 0x38, 0x00, | C6: 80 0A BF 13 02 00 00 04 00 00 19 39 | D6: Key status motor running?
A7: 0x00, 0x4D}; | C7: D0 07 BF 5C FF 3F FF 00 0B | D7: LCM to Global Light Dimmer
A8: char cdc_rad_cdstatstoppause [] = {0x18, 0x0A, 0x68, 0x39, 0x00, 0x02, | C8: E8 05 D0 59 11 02 77 | D8: RLS to LCM Light control Status
A9: 0x00, 0x3F, 0x00, 0x01, 0x01};//, 0x7E};
A11: char rad_cdc_cdcontrolmode7fuct00 [] = {0x68, 0x05, 0x18, 0x38, 0x07,
A12: 0x00, 0x4A};
A13: char cdc_rad_cdstatplaypause [] = {0x18, 0x0A, 0x68, 0x39, 0x02, 0x02,
A14: 0x00, 0x3F, 0x00, 0x01, 0x01};//, 0x7C};
A16: char rad_cdc_cdcontrolrandomoff [] = {0x68, 0x05, 0x18, 0x38, 0x08,
A17: 0x00, 0x45};
A19: char rad_cdc_cdcontrolplay [] = {0x68, 0x05, 0x18, 0x38, 0x03, 0x00, 0x4E};
A20: char cdc_rad_cdstatplayplay [] = {0x18, 0x0A, 0x68, 0x39, 0x02, 0x09,
A21: 0x00, 0x3F, 0x00, 0x01, 0x01};//, 0x77};
A23: char tel_ike_clrscr [] = {0xc8, 0x05, 0x80, 0x23, 0x41, 0x20};
A25: char mfl_rad_minus [] = {0x50, 0x04, 0x68, 0x32, 0x10};
... A67: char glo_all_unlock [] = {0x00, 0x04, 0xBF, 0x72, 0x22, 0xEB};

Sheet E46 codes tested
A1: E46 IBUS codes
A2: All codes tested on a E46 318ti
A4: Bf 7d 00 05 00 30 f7 - Open sunroof and possibly unlock
A5: Bf 7d 00 05 00 20 chk - Open sunroof and lock
A6: Close sunroof and possibly unlock - 00 05 00 70 bf bf 7d
A7: Bf 7d 00 05 00 60 chk - close sunroof and lock
A8: Bf 7d 00 05 00 00 chk - sliding lock
A9: Bf 7d 00 05 00 10 chk - sliding unlock
A11: 3f 05 00 0c 7e 01 chk - sunroof open a piece
A12: 3f 05 00 0c 7f 01 chk - sunroof close a piece
A14: 3f 05 00 0c 52 01 chk - open driver's side front window a piece
A15: 3f 05 00 0c 53 01 chk - windows on the front driver's side close a piece
... A41: 3f 05 00 0c 62 01 chk - Windshield washer front spraying
A44: 0x 00 04 bf 76 chk - Flashing: 2 = warning lights, 4 = low beam, high beam 8 = | I44: 08 00 04 bf 76
A45: 3f 05 00 0c 70 01 chk - hazard lights (IKE + LCM) + Innenraumbel. dim
A46: 3f 05 00 0c 75 01 chk - hazard lights (LCM) for 3 seconds
A47: 3f 0b BF 0c 00 00 00 00 00 00 01 06 chk - Fog
A48: 3f 0b BF 0c 00 00 00 00 00 40 00 06 chk - left tail light (+ A)
A49: 3f 0b BF 0c 00 00 00 00 00 00 08 0c chk - rear light (+ A)
A50: 3f 0b BF 0c 00 00 00 00 01 00 00 06 chk - brake light above
A51: 3f 0b BF 0c 00 00 00 00 08 00 00 06 chk - brake light left (+ A)
A52: 3f 0b BF 0c 00 00 00 00 10 00 00 06 chk - Brake Light Right (+ A)
A53: 3f 0b BF 0c 00 00 00 00 00 02 00 06 chk - front right low beam
A54: 3f 0b BF 0c 00 00 00 00 00 04 00 06 chk - low beam, front left
A55: 3f 0b BF 0c 10 00 00 00 00 00 00 06 chk - low beam delayed front + rear
A56: 3f 0b BF 0c 00 00 00 00 00 10 00 06 chk - Main beam left + low beams on both sides
... A166: 3B 05 80 41 09 08 cs DE-ACTIVITE SPEELIMIT in OBC

Sheet Calculations
A1: Messages to the control units for the E39 series: address 00 Hex (transmitter 3FH / DIS) | B1: Column1 | C1: Column2 | D1: Column3 | E1: Column4 | F1: Column5 | G1: Column6 | H1: Message
A2: <3F 05 00> 0C 00 44 <XOR> Fenster Fahrerseite hinten schließen <3F 05 00> 00 44 0C <XOR> driver's side window close behind | C2: =RIGHT(LEFT(A2,19),2) -> 44 | D2: =HEX2BIN(C2,8) -> 01000100 | E2: 1001000 | F2: =BIN2HEX(E2,8) -> 00000048 | G2: 34 | H2: =CONCATENATE("3F 05 00 0C 00 ",Table1[[#This Row],[Column2]]) -> 3F 05 00 0C 00 44
A3: <3F 05 00> 0C 00 45 <XOR> Fenster Fahrerseite hinten öffnen <3F 05 00> 00 45 0C <XOR> driver's side window open behind | C3: =RIGHT(LEFT(A3,19),2) -> 45 | D3: =HEX2BIN(C3,8) -> 01000101 | E3: 1001001 | F3: =BIN2HEX(E3,8) -> 00000049 | G3: 35 | H3: =CONCATENATE("3F 05 00 0C 00 ",Table1[[#This Row],[Column2]]) -> 3F 05 00 0C 00 45
A4: <3F 05 00> 0C 00 46 <XOR> Fenster Beifahrerseite hinten schließen <3F 05 00> 00 46 0C <XOR> passenger side window close behind | C4: =RIGHT(LEFT(A4,19),2) -> 46 | D4: =HEX2BIN(C4,8) -> 01000110 | E4: 1001010 | F4: =BIN2HEX(E4,8) -> 0000004A | G4: 36 | H4: =CONCATENATE("3F 05 00 0C 00 ",Table1[[#This Row],[Column2]]) -> 3F 05 00 0C 00 46
A5: <3F 05 00> 0C 00 47 <XOR> Fenster Beifahrerseite hinten öffnen <3F 05 00> 00 47 0C <XOR> open rear passenger side window | C5: =RIGHT(LEFT(A5,19),2) -> 47 | D5: =HEX2BIN(C5,8) -> 01000111 | E5: 1001011 | F5: =BIN2HEX(E5,8) -> 0000004B | G5: 37 | H5: =CONCATENATE("3F 05 00 0C 00 ",Table1[[#This Row],[Column2]]) -> 3F 05 00 0C 00 47
A6: ? driver's side window close front | C6: 56 | D6: 01001000 | H6: =CONCATENATE("3F 05 00 0C 00 ",Table1[[#This Row],[Column2]]) -> 3F 05 00 0C 00 56
A7: ? driver's side window open front | C7: 55 | D7: 01001001 | H7: =CONCATENATE("3F 05 00 0C 00 ",Table1[[#This Row],[Column2]]) -> 3F 05 00 0C 00 55
A8: ? passenger side window close front | C8: 58 | D8: 01001010 | H8: =CONCATENATE("3F 05 00 0C 00 ",Table1[[#This Row],[Column2]]) -> 3F 05 00 0C 00 58
A9: ? passenger side window open front | C9: 57 | D9: 01001011 | H9: =CONCATENATE("3F 05 00 0C 00 ",Table1[[#This Row],[Column2]]) -> 3F 05 00 0C 00 57
A10: <3F 05 00> 0C 00 65 <XOR> alle Fenster öffnen <3F 05 00> 00 65 0C <XOR> open all windows | C10: =RIGHT(LEFT(A10,19),2) -> 65 | D10: =HEX2BIN(C10,8) -> 01100101 | H10: =CONCATENATE("3F 05 00 0C 00 ",Table1[[#This Row],[Column2]]) -> 3F 05 00 0C 00 65
A11: ? close all windows | C11: =BIN2HEX(D11,2) -> 64 | D11: 01100100 | H11: =CONCATENATE("3F 05 00 0C 00 ",Table1[[#This Row],[Column2]]) -> 3F 05 00 0C 00 64
A12: <3F 05 00> 0C 00 66 <XOR> Schiebedach öffnen <3F 05 00> 00 66 0C <XOR> open sunroof | C12: =RIGHT(LEFT(A12,19),2) -> 66 | D12: =HEX2BIN(C12,8) -> 01100110 | H12: =CONCATENATE("3F 05 00 0C 00 ",Table1[[#This Row],[Column2]]) -> 3F 05 00 0C 00 66
A13: ? close sunroof | C13: =BIN2HEX(D13,2) -> 67 | D13: 01100111 | H13: =CONCATENATE("3F 05 00 0C 00 ",Table1[[#This Row],[Column2]]) -> 3F 05 00 0C 00 67
A14: <3F 05 00> 0C 00 0B <XOR> Zentralverriegelung öffen/schließen <3F 05 00> 0C 00 0B <XOR> Central close openable / | C14: =RIGHT(LEFT(A14,19),2) -> 0B | D14: =HEX2BIN(C14,8) -> 00001011 | H14: =CONCATENATE("3F 05 00 0C 00 ",Table1[[#This Row],[Column2]]) -> 3F 05 00 0C 00 0B
A15: <3F 05 00> 0C 00 40 <XOR> Kofferraum öffnen <3F 05 00> 00 40 0C <XOR> trunk open | C15: =RIGHT(LEFT(A15,19),2) -> 40 | D15: =HEX2BIN(C15,8) -> 01000000 | H15: =CONCATENATE("3F 05 00 0C 00 ",Table1[[#This Row],[Column2]]) -> 3F 05 00 0C 00 40
A16: <3F 05 00> 0C 00 00 <XOR> Fahrersitz nach vorne verschieben <3F 05 00> 00 00 0C <XOR> seat move forward | C16: =RIGHT(LEFT(A16,19),2) -> 00 | D16: =HEX2BIN(C16,8) -> 00000000 | H16: =CONCATENATE("3F 05 00 0C 00 ",Table1[[#This Row],[Column2]]) -> 3F 05 00 0C 00 00
A17: <3F 05 00> 0C 00 01 <XOR> Fahrersitz nach hinten verschieben <3F 05 00> 00 01 0C <XOR> seat rearwards | C17: =RIGHT(LEFT(A17,19),2) -> 01 | D17: =HEX2BIN(C17,8) -> 00000001 | H17: =CONCATENATE("3F 05 00 0C 00 ",Table1[[#This Row],[Column2]]) -> 3F 05 00 0C 00 01 | Q17: 0100 | R17: =BIN2DEC(Q17) -> 4
A18: <3F 06 00> 0C 01 31 01 <XOR> Spiegel Fahrerseite einklappen <3F 06 00> 01 31 01 0C <XOR> driver side mirror fold | C18: =RIGHT(LEFT(A18,19),2) -> 31 | D18: =HEX2BIN(C18,8) -> 00110001 | H18: =CONCATENATE("3F 05 00 0C 00 ",Table1[[#This Row],[Column2]]) -> 3F 05 00 0C 00 31
A19: <3F 06 00> 0C 01 30 01 <XOR> Spiegel Fahrerseite ausklappen <3F 06 00> 01 30 01 0C <XOR> driver side mirror fold out | C19: =RIGHT(LEFT(A19,19),2) -> 30 | D19: =HEX2BIN(C19,8) -> 00110000 | H19: =CONCATENATE("3F 05 00 0C 00 ",Table1[[#This Row],[Column2]]) -> 3F 05 00 0C 00 30
A20: <3F 06 00> 0C 02 31 01 <XOR> Spiegel Beifahrerseite einklappen <3F 06 00> 02 31 01 0C <XOR> passenger side mirror fold | C20: =RIGHT(LEFT(A20,19),2) -> 31 | D20: =HEX2BIN(C20,8) -> 00110001 | H20: =CONCATENATE("3F 05 00 0C 00 ",Table1[[#This Row],[Column2]]) -> 3F 05 00 0C 00 31
A21: <3F 06 00> 0C 02 30 01 <XOR> Spiegel Beifahrerseite ausklappen <3F 06 00> 02 30 01 0C <XOR> passenger side mirror fold out | C21: =RIGHT(LEFT(A21,19),2) -> 30 | D21: =HEX2BIN(C21,8) -> 00110000 | H21: =CONCATENATE("3F 05 00 0C 00 ",Table1[[#This Row],[Column2]]) -> 3F 05 00 0C 00 30
E25: 46 | F25: =CHAR(HEX2DEC(E25)) -> F
E26: 45 | F26: =HEX2BIN(E26,8) -> 01000101
F27: 01 00 01 11 | G27: =BIN2HEX(SUBSTITUTE(F27," ",""),2) -> 47
F28: 01 01 01 01 | G28: =BIN2HEX(SUBSTITUTE(F28," ",""),2) -> 55
F29: e46 | G29: e39 | H29: e39 bin | K29: e46 | P29: e39
F30: =BIN2DEC(RIGHT(M30,6)) -> 1 | G30: =BIN2DEC(RIGHT(R30,6)) -> 5 | H30: =DEC2BIN(G30,6) -> 000101 | K30: dr w o | L30: 41 | M30: =HEX2BIN(L30,8) -> 01000001 | N30: =CONCATENATE(LEFT(M30,2)," ",RIGHT(LEFT(M30,4),2)," ",RIGHT(LEFT(M30,6),2)," ",RIGHT(LEFT(M30,8),2)," ") -> 01 00 00 01 | P30: dr w o | Q30: 45 | R30: =HEX2BIN(Q30,8) -> 01000101 | S30: =CONCATENATE(LEFT(R30,2)," ",RIGHT(LEFT(R30,4),2)," ",RIGHT(LEFT(R30,6),2)," ",RIGHT(LEFT(R30,8),2)," ") -> 01 00 01 01
F31: =BIN2DEC(RIGHT(M31,6)) -> 2 | G31: =BIN2DEC(RIGHT(R31,6)) -> 4 | H31: =DEC2BIN(G31,6) -> 000100 | K31: dr w c | L31: 42 | M31: =HEX2BIN(L31,8) -> 01000010 | N31: =CONCATENATE(LEFT(M31,2)," ",RIGHT(LEFT(M31,4),2)," ",RIGHT(LEFT(M31,6),2)," ",RIGHT(LEFT(M31,8),2)," ") -> 01 00 00 10 | P31: dr w c | Q31: 44 | R31: =HEX2BIN(Q31,8) -> 01000100 | S31: =CONCATENATE(LEFT(R31,2)," ",RIGHT(LEFT(R31,4),2)," ",RIGHT(LEFT(R31,6),2)," ",RIGHT(LEFT(R31,8),2)," ") -> 01 00 01 00
F32: =BIN2DEC(RIGHT(M32,6)) -> 3 | G32: =BIN2DEC(RIGHT(R32,6)) -> 7 | H32: =DEC2BIN(G32,6) -> 000111 | K32: pr w o | L32: 43 | M32: =HEX2BIN(L32,8) -> 01000011 | N32: =CONCATENATE(LEFT(M32,2)," ",RIGHT(LEFT(M32,4),2)," ",RIGHT(LEFT(M32,6),2)," ",RIGHT(LEFT(M32,8),2)," ") -> 01 00 00 11 | P32: pr w o | Q32: 47 | R32: =HEX2BIN(Q32,8) -> 01000111 | S32: =CONCATENATE(LEFT(R32,2)," ",RIGHT(LEFT(R32,4),2)," ",RIGHT(LEFT(R32,6),2)," ",RIGHT(LEFT(R32,8),2)," ") -> 01 00 01 11
F33: =BIN2DEC(RIGHT(M33,6)) -> 4 | G33: =BIN2DEC(RIGHT(R33,6)) -> 6 | H33: =DEC2BIN(G33,6) -> 000110 | K33: pr w c | L33: 44 | M33: =HEX2BIN(L33,8) -> 01000100 | N33: =CONCATENATE(LEFT(M33,2)," ",RIGHT(LEFT(M33,4),2)," ",RIGHT(LEFT(M33,6),2)," ",RIGHT(LEFT(M33,8),2)," ") -> 01 00 01 00 | P33: pr w c | Q33: 46 | R33: =HEX2BIN(Q33,8) -> 01000110 | S33: =CONCATENATE(LEFT(R33,2)," ",RIGHT(LEFT(R33,4),2)," ",RIGHT(LEFT(R33,6),2)," ",RIGHT(LEFT(R33,8),2)," ") -> 01 00 01 10
F34: =BIN2DEC(RIGHT(M34,6)) -> 18 | G34: =BIN2DEC(RIGHT(R34,6)) -> 21 | H34: =DEC2BIN(G34,6) -> 010101 | K34: df w o | L34: 52 | M34: =HEX2BIN(L34,8) -> 01010010 | N34: =CONCATENATE(LEFT(M34,2)," ",RIGHT(LEFT(M34,4),2)," ",RIGHT(LEFT(M34,6),2)," ",RIGHT(LEFT(M34,8),2)," ") -> 01 01 00 10 | P34: df w o | Q34: 55 | R34: =HEX2BIN(Q34,8) -> 01010101 | S34: =CONCATENATE(LEFT(R34,2)," ",RIGHT(LEFT(R34,4),2)," ",RIGHT(LEFT(R34,6),2)," ",RIGHT(LEFT(R34,8),2)," ") -> 01 01 01 01
F35: =BIN2DEC(RIGHT(M35,6)) -> 19 | G35: =BIN2DEC(RIGHT(R35,6)) -> 22 | H35: =DEC2BIN(G35,6) -> 010110 | K35: df w c | L35: 53 | M35: =HEX2BIN(L35,8) -> 01010011 | N35: =CONCATENATE(LEFT(M35,2)," ",RIGHT(LEFT(M35,4),2)," ",RIGHT(LEFT(M35,6),2)," ",RIGHT(LEFT(M35,8),2)," ") -> 01 01 00 11 | P35: df w c | Q35: 56 | R35: =HEX2BIN(Q35,8) -> 01010110 | S35: =CONCATENATE(LEFT(R35,2)," ",RIGHT(LEFT(R35,4),2)," ",RIGHT(LEFT(R35,6),2)," ",RIGHT(LEFT(R35,8),2)," ") -> 01 01 01 10
F36: =BIN2DEC(RIGHT(M36,6)) -> 20 | G36: =BIN2DEC(RIGHT(R36,6)) -> 23 | H36: =DEC2BIN(G36,6) -> 010111 | K36: pf w o | L36: 54 | M36: =HEX2BIN(L36,8) -> 01010100 | N36: =CONCATENATE(LEFT(M36,2)," ",RIGHT(LEFT(M36,4),2)," ",RIGHT(LEFT(M36,6),2)," ",RIGHT(LEFT(M36,8),2)," ") -> 01 01 01 00 | P36: pf w o | Q36: 57 | R36: =HEX2BIN(Q36,8) -> 01010111 | S36: =CONCATENATE(LEFT(R36,2)," ",RIGHT(LEFT(R36,4),2)," ",RIGHT(LEFT(R36,6),2)," ",RIGHT(LEFT(R36,8),2)," ") -> 01 01 01 11
F37: =BIN2DEC(RIGHT(M37,6)) -> 21 | G37: =BIN2DEC(RIGHT(R37,6)) -> 24 | H37: =DEC2BIN(G37,6) -> 011000 | K37: pf w c | L37: 55 | M37: =HEX2BIN(L37,8) -> 01010101 | N37: =CONCATENATE(LEFT(M37,2)," ",RIGHT(LEFT(M37,4),2)," ",RIGHT(LEFT(M37,6),2)," ",RIGHT(LEFT(M37,8),2)," ") -> 01 01 01 01 | P37: pf w c | Q37: 58 | R37: =HEX2BIN(Q37,8) -> 01011000 | S37: =CONCATENATE(LEFT(R37,2)," ",RIGHT(LEFT(R37,4),2)," ",RIGHT(LEFT(R37,6),2)," ",RIGHT(LEFT(R37,8),2)," ") -> 01 01 10 00
K38: aa bb cc dd | P38: aa bb cc dd
K39: aa | L39: 01 | P39: aa | Q39: 01
K40: bb | L40: 00 rear, 01 front | P40: bb | Q40: 00 rear, 01 front?
K41: cc | L41: 00 driver, 01 passenger | P41: cc
K42: dd | L42: open/close | P42: dd

Sheet Wheel
A1: http://www.bmwgm5.com/IBUS.htm
A4: Button | C4: Device | D4: Button | E4: IBUS
A5: Volume + | C5: 0xAD/0x52 | D5: 0x0A/0xF5 | E5: 50 04 68 32 11 1F(Vol+)
A6: Volume - | C6: 0xAD/0x52 | D6: 0x0B/0xF4 | E6: 50 04 68 32 10 1E(Vol-)
A7: Band | C7: 0xAD/0x52 | D7: 0x12/0xED
A8: Mute | C8: 0xAD/0x52 | D8: 0x0C/0xF3 | E8: 50 04 68 3B 80 27(Dial)
A9: Up | C9: 0xAD/0x52 | D9: 0x40/0xBF
A10: Down | C10: 0xAD/0x52 | D10: 0x41/0xBE
A11: Left | C11: 0xAD/0x52 | D11: 0x42/0xBD | E11: 50 04 68 3B 08 0F (Prev)
A12: Right | C12: 0xAD/0x52 | D12: 0x43/0xBC | E12: 50 04 68 3B 01 06(Next)
A13: Function | C13: 0xAD/0x52 | D13: 0x19/0xE6
A14: Audio | C14: 0xAD/0x52 | D14: 0x0D/0xF2
A15: CD | C15: 0xAD/0x52 | D15: 0x1E/0xE1
A16: Pause | C16: 0xAD/0x52 | D16: 0x58/0xA7
A17: Tuner | C17: 0xAD/0x52 | D17: 0x1C/0xE3
A21: Button | C21: IBUS Message (Hex) | D21: Includes check sum | H21: Volume - | J21: 50 04 68 32 10 1E
A22: Volume + | C22: 50 04 68 32 11 1F | H22: Volume + | J22: 50 04 68 32 11 1F
A23: Volume - | C23: 50 04 68 32 10 1E
H24: Next (Pressed) | J24: 50 04 68 3B 01 06 | K24: skip
A25: Next (Pressed) | C25: 50 04 68 3B 01 06 | H25: Previous (Pressed) | J25: 50 04 68 3B 08 0F | K25: previous
A26: Next (1 Second) | C26: 50 04 68 3B 11 16 | H26: Next (1 Second) | J26: 50 04 68 3B 11 16 | K26: FFW
A27: Next (Released) | C27: 50 04 68 3B 21 26 | H27: Previous (1 Second) | J27: 50 04 68 3B 18 1F | K27: FRWD
A28: Previous (Pressed) | C28: 50 04 68 3B 08 0F | H28: Next (Released) | J28: 50 04 68 3B 21 26
A29: Previous (1 Second) | C29: 50 04 68 3B 18 1F | H29: Previous (Released) | J29: 50 04 68 3B 28 2F
A30: Previous (Released) | C30: 50 04 68 3B 28 2F
A31: R/T | C31: 50 03 C8 01 9A | H31: R/T | J31: 50 03 C8 01 9A
A32: Dial (Pressed) | C32: 50 04 C8 3B 80 27 | H32: Dial (Pressed) | J32: 50 04 C8 3B 80 27
A33: Dial (1 Second) | C33: 50 04 C8 3B 90 37 | H33: Dial (1 Second) | J33: 50 04 C8 3B 90 37
A34: Dial (Released) | C34: 50 04 C8 3B A0 07 | H34: Dial (Released) | J34: 50 04 C8 3B A0 07

Sheet Nave coder
A1: The third bit in the Ibus message
A3: 70 03 80 00 F3 | B3: =LEFT(RIGHT(A3,5),2) -> 00 | C3: Cmd_0x00
A4: 70 03 80 01 F2 | B4: =LEFT(RIGHT(A4,5),2) -> 01 | C4: Device status request
A5: 70 03 80 02 F1 | B5: =LEFT(RIGHT(A5,5),2) -> 02 | C5: Device status ready
A6: 70 03 80 03 F0 | B6: =LEFT(RIGHT(A6,5),2) -> 03 | C6: Bus status request
A7: 70 03 80 04 F7 | B7: =LEFT(RIGHT(A7,5),2) -> 04 | C7: Bus status
A8: 70 03 80 05 F6 | B8: =LEFT(RIGHT(A8,5),2) -> 05 | C8: Backlight Control
A9: 70 03 80 06 F5 | B9: =LEFT(RIGHT(A9,5),2) -> 06 | C9: Identification
A10: 70 03 80 07 F4 | B10: =LEFT(RIGHT(A10,5),2) -> 07 | C10: Gong status
A11: 70 03 80 08 FB | B11: =LEFT(RIGHT(A11,5),2) -> 08 | C11: Cmd_0x08
A12: 70 03 80 09 FA | B12: =LEFT(RIGHT(A12,5),2) -> 09 | C12: Cmd_0x09
A13: 70 03 80 0A F9 | B13: =LEFT(RIGHT(A13,5),2) -> 0A | C13: Cmd_0x0A
A14: 70 03 80 0B F8 | B14: =LEFT(RIGHT(A14,5),2) -> 0B | C14: Cmd_0x0B
... A258: 70 03 80 FF 0C | B258: =LEFT(RIGHT(A258,5),2) -> FF | C258: Cmd_0xFF
